<?xml version="1.0" encoding="utf-8"?>
<!-- This URDF was automatically created by SolidWorks to URDF Exporter! Originally created by Stephen Brawner (brawner@gmail.com) 
     Commit Version: 1.6.0-4-g7f85cfe  Build Version: 1.6.7995.38578
     For more information, please see http://wiki.ros.org/sw_urdf_exporter -->
<robot
  name="jaka_humanoid">

  <link name="base_geom">
  </link>
  <joint name="base_fixed_joint" type="fixed">
    <origin xyz="0 0 0" rpy="0 0 -1.5708"/>
    <parent link="base_geom"/>
    <child link="base_link"/>
  </joint>


  <link
    name="base_link">
    <inertial>
      <origin
        xyz="3.56051837431537E-06 0.000113782895444087 0.0103683192174064"
        rpy="0 0 0" />
      <mass
        value="8.534795777719" />
      <inertia
        ixx="0.0313527429203055"
        ixy="-1.01541581029892E-06"
        ixz="-1.07263922262646E-06"
        iyy="0.0504190458696739"
        iyz="-8.99294508164332E-05"
        izz="0.0475793827870453" />
    </inertial>
    <visual>
      <origin
        xyz="0 0 0"
        rpy="0 0 0" />
      <geometry>
        <mesh
          filename="package://jaka_humanoid/meshes/base_link.STL" />
      </geometry>
      <material
        name="">
        <color
          rgba="0.698039215686274 0.698039215686274 0.698039215686274 1" />
      </material>
    </visual>
    <!-- <collision>
      <origin
        xyz="0 0 0"
        rpy="0 0 0" />
      <geometry>
        <mesh
          filename="package://jaka_humanoid/meshes/base_link.STL" />
      </geometry>
    </collision> -->
  </link>
  <link
    name="left_hip_pitch_link">
    <inertial>
      <origin
        xyz="-6.92170643301626E-08 -1.51282743337602E-05 0.059552778136023"
        rpy="0 0 0" />
      <mass
        value="3.9634339446951" />
      <inertia
        ixx="0.00771849424837419"
        ixy="-8.53395660232772E-07"
        ixz="1.46949827377146E-09"
        iyy="0.00782429269137684"
        iyz="2.08211386353778E-06"
        izz="0.00773849877963618" />
    </inertial>
    <visual>
      <origin
        xyz="0 0 0"
        rpy="0 0 0" />
      <geometry>
        <mesh
          filename="package://jaka_humanoid/meshes/LINK_L1.STL" />
      </geometry>
      <material
        name="">
        <color
          rgba="0.698039215686274 0.698039215686274 0.698039215686274 1" />
      </material>
    </visual>
    <collision>
      <origin
        xyz="0 0 0"
        rpy="0 0 0" />
      <geometry>
        <mesh
          filename="package://jaka_humanoid/meshes/LINK_L1.STL" />
      </geometry>
    </collision>
  </link>
  <joint
    name="left_hip_pitch_joint"
    type="revolute">
    <origin
      xyz="-0.106 0 0"
      rpy="3.1416 1.5708 0" />
    <parent
      link="base_link" />
    <child
      link="left_hip_pitch_link" />
    <axis
      xyz="0 0 1" />
    <limit
      lower="-2"
      upper="2"
      effort="500"
      velocity="30" />
  </joint>
  <link
    name="left_hip_roll_link">
    <inertial>
      <origin
        xyz="-0.00161389199959538 0.109413538339146 0.000486968452788193"
        rpy="0 0 0" />
      <mass
        value="3.77738840138226" />
      <inertia
        ixx="0.017398908144898"
        ixy="-0.000311849670723211"
        ixz="1.39056091881881E-05"
        iyy="0.0097749180467322"
        iyz="-0.000414031288516339"
        izz="0.0146465644838559" />
    </inertial>
    <visual>
      <origin
        xyz="0 0 0"
        rpy="0 0 0" />
      <geometry>
        <mesh
          filename="package://jaka_humanoid/meshes/LINK_L2.STL" />
      </geometry>
      <material
        name="">
        <color
          rgba="0.698039215686274 0.698039215686274 0.698039215686274 1" />
      </material>
    </visual>
    <!-- <collision>
      <origin
        xyz="0 0 0"
        rpy="0 0 0" />
      <geometry>
        <mesh
          filename="package://jaka_humanoid/meshes/LINK_L2.STL" />
      </geometry>
    </collision> -->
  </link>
  <joint
    name="left_hip_roll_joint"
    type="revolute">
    <origin
      xyz="0 0 0.061"
      rpy="1.5708 1.5708 0" />
    <parent
      link="left_hip_pitch_link" />
    <child
      link="left_hip_roll_link" />
    <axis
      xyz="0 0 1" />
    <limit
      lower="-2"
      upper="2"
      effort="500"
      velocity="30" />
  </joint>
  <link
    name="left_hip_yaw_link">
    <inertial>
      <origin
        xyz="0.000700320772332008 0.00969139564417535 -0.135462623259175"
        rpy="0 0 0" />
      <mass
        value="3.59262397650648" />
      <inertia
        ixx="0.0302831726867375"
        ixy="2.76348322471797E-05"
        ixz="0.000252356115220069"
        iyy="0.0324036832512038"
        iyz="0.00149317453880794"
        izz="0.014224840085199" />
    </inertial>
    <visual>
      <origin
        xyz="0 0 0"
        rpy="0 0 0" />
      <geometry>
        <mesh
          filename="package://jaka_humanoid/meshes/LINK_L3.STL" />
      </geometry>
      <material
        name="">
        <color
          rgba="0.698039215686274 0.698039215686274 0.698039215686274 1" />
      </material>
    </visual>
    <collision>
      <origin
        xyz="0 0 0"
        rpy="0 0 0" />
      <geometry>
        <mesh
          filename="package://jaka_humanoid/meshes/LINK_L3.STL" />
      </geometry>
    </collision>
  </link>
  <joint
    name="left_hip_yaw_joint"
    type="revolute">
    <origin
      xyz="0 0.183 0"
      rpy="1.5708 0 0" />
    <parent
      link="left_hip_roll_link" />
    <child
      link="left_hip_yaw_link" />
    <axis
      xyz="0 0 1" />
    <limit
      lower="-2"
      upper="2"
      effort="500"
      velocity="30" />
  </joint>
  <link
    name="left_knee_link">
    <inertial>
      <origin
        xyz="0.111701578307267 0.00355403504398386 0.0512295108100788"
        rpy="0 0 0" />
      <mass
        value="8.60818099327112" />
      <inertia
        ixx="0.0274097334369474"
        ixy="0.00545179651823928"
        ixz="0.000199884218813842"
        iyy="0.168526145595671"
        iyz="-1.74301620560199E-06"
        izz="0.165681955419885" />
    </inertial>
    <visual>
      <origin
        xyz="0 0 0"
        rpy="0 0 0" />
      <geometry>
        <mesh
          filename="package://jaka_humanoid/meshes/LINK_L4.STL" />
      </geometry>
      <material
        name="">
        <color
          rgba="0.698039215686274 0.698039215686274 0.698039215686274 1" />
      </material>
    </visual>
    <!-- <collision>
      <origin
        xyz="0 0 0"
        rpy="0 0 0" />
      <geometry>
        <mesh
          filename="package://jaka_humanoid/meshes/LINK_L4.STL" />
      </geometry>
    </collision> -->
  </link>
  <joint
    name="left_knee_joint"
    type="revolute">
    <origin
      xyz="-0.0516 -0.005 -0.237"
      rpy="0 1.5708 0" />
    <parent
      link="left_hip_yaw_link" />
    <child
      link="left_knee_link" />
    <axis
      xyz="0 0 -1" />
    <limit
      lower="-2"
      upper="2"
      effort="500"
      velocity="30" />
  </joint>
  <link
    name="left_ankle_pitch_link">
    <inertial>
      <origin
        xyz="6.62661078232318E-08 0.00426165224024064 0.0516144830011017"
        rpy="0 0 0" />
      <mass
        value="4.14002049154091" />
      <inertia
        ixx="0.0085990272817376"
        ixy="2.24142896102055E-09"
        ixz="-8.53395641261122E-07"
        iyy="0.00802808945553078"
        iyz="2.25086671400731E-06"
        izz="0.00870709893558791" />
    </inertial>
    <visual>
      <origin
        xyz="0 0 0"
        rpy="0 0 0" />
      <geometry>
        <mesh
          filename="package://jaka_humanoid/meshes/LINK_L5.STL" />
      </geometry>
      <material
        name="">
        <color
          rgba="0.698039215686274 0.698039215686274 0.698039215686274 1" />
      </material>
    </visual>
    <!-- <collision>
      <origin
        xyz="0 0 0"
        rpy="0 0 0" />
      <geometry>
        <mesh
          filename="package://jaka_humanoid/meshes/LINK_L5.STL" />
      </geometry>
    </collision> -->
  </link>
  <joint
    name="left_ankle_pitch_joint"
    type="revolute">
    <origin
      xyz="0.37 -0.005 0"
      rpy="0 0 0" />
    <parent
      link="left_knee_link" />
    <child
      link="left_ankle_pitch_link" />
    <axis
      xyz="0 0 -1" />
    <limit
      lower="-2"
      upper="2"
      effort="500"
      velocity="30" />
  </joint>
  <link
    name="left_ankle_roll_link">
    <inertial>
      <origin
        xyz="5.58153339869083E-06 0.0507733542549267 -0.0331828584344808"
        rpy="0 0 0" />
      <mass
        value="4.46370362417452" />
      <inertia
        ixx="0.0280531352875821"
        ixy="-5.78611601880667E-07"
        ixz="7.74244017617182E-07"
        iyy="0.0225586720016511"
        iyz="-0.00350808779823298"
        izz="0.0150950458764849" />
    </inertial>
    <visual>
      <origin
        xyz="0 0 0"
        rpy="0 0 0" />
      <geometry>
        <mesh
          filename="package://jaka_humanoid/meshes/LINK_L6.STL" />
      </geometry>
      <material
        name="">
        <color
          rgba="0.698039215686274 0.698039215686274 0.698039215686274 1" />
      </material>
    </visual>
    <collision>
      <origin
        xyz="0 0 0"
        rpy="0 0 0" />
      <geometry>
        <mesh
          filename="package://jaka_humanoid/meshes/LINK_L6.STL" />
      </geometry>
    </collision>
  </link>
  <joint
    name="left_ankle_roll_joint"
    type="revolute">
    <origin
      xyz="0 0.0725 0.0516"
      rpy="1.5708 1.5708 0" />
    <parent
      link="left_ankle_pitch_link" />
    <child
      link="left_ankle_roll_link" />
    <axis
      xyz="0 0 -1" />
    <limit
      lower="-2"
      upper="2"
      effort="500"
      velocity="30" />
  </joint>
  <link
    name="right_hip_pitch_link">
    <inertial>
      <origin
        xyz="6.92164925653049E-08 1.51282748375031E-05 0.0595527781372258"
        rpy="0 0 0" />
      <mass
        value="3.96343394458631" />
      <inertia
        ixx="0.00771849424840239"
        ixy="-8.53395477027585E-07"
        ixz="-1.46959496734758E-09"
        iyy="0.0078242926913489"
        iyz="-2.08211379955066E-06"
        izz="0.00773849877951949" />
    </inertial>
    <visual>
      <origin
        xyz="0 0 0"
        rpy="0 0 0" />
      <geometry>
        <mesh
          filename="package://jaka_humanoid/meshes/LINK_R1.STL" />
      </geometry>
      <material
        name="">
        <color
          rgba="0.698039215686274 0.698039215686274 0.698039215686274 1" />
      </material>
    </visual>
    <collision>
      <origin
        xyz="0 0 0"
        rpy="0 0 0" />
      <geometry>
        <mesh
          filename="package://jaka_humanoid/meshes/LINK_R1.STL" />
      </geometry>
    </collision>
  </link>
  <joint
    name="right_hip_pitch_joint"
    type="revolute">
    <origin
      xyz="0.106 0 0"
      rpy="0 1.5708 0" />
    <parent
      link="base_link" />
    <child
      link="right_hip_pitch_link" />
    <axis
      xyz="0 0 -1" />
    <limit
      lower="-2"
      upper="2"
      effort="500"
      velocity="30" />
  </joint>
  <link
    name="right_hip_roll_link">
    <inertial>
      <origin
        xyz="-0.0016146123021254 0.10941376048029 -0.000488039420374099"
        rpy="0 0 0" />
      <mass
        value="3.7773115346162" />
      <inertia
        ixx="0.0173986187585205"
        ixy="-0.000311962535762005"
        ixz="-1.36546661845248E-05"
        iyy="0.00977467337602778"
        iyz="0.000413945427803824"
        izz="0.0146463881285214" />
    </inertial>
    <visual>
      <origin
        xyz="0 0 0"
        rpy="0 0 0" />
      <geometry>
        <mesh
          filename="package://jaka_humanoid/meshes/LINK_R2.STL" />
      </geometry>
      <material
        name="">
        <color
          rgba="0.698039215686274 0.698039215686274 0.698039215686274 1" />
      </material>
    </visual>
    <!-- <collision>
      <origin
        xyz="0 0 0"
        rpy="0 0 0" />
      <geometry>
        <mesh
          filename="package://jaka_humanoid/meshes/LINK_R2.STL" />
      </geometry>
    </collision> -->
  </link>
  <joint
    name="right_hip_roll_joint"
    type="revolute">
    <origin
      xyz="0 0 0.061"
      rpy="1.5708 1.5708 0" />
    <parent
      link="right_hip_pitch_link" />
    <child
      link="right_hip_roll_link" />
    <axis
      xyz="0 0 -1" />
    <limit
      lower="-2"
      upper="2"
      effort="500"
      velocity="30" />
  </joint>
  <link
    name="right_hip_yaw_link">
    <inertial>
      <origin
        xyz="0.000694563219510266 0.00968700464199349 0.135454808018665"
        rpy="0 0 0" />
      <mass
        value="3.59228381979526" />
      <inertia
        ixx="0.0302813066755261"
        ixy="2.86623051709676E-05"
        ixz="-0.000252080563411604"
        iyy="0.0324025678598891"
        iyz="-0.00149175894663388"
        izz="0.0142239522611104" />
    </inertial>
    <visual>
      <origin
        xyz="0 0 0"
        rpy="0 0 0" />
      <geometry>
        <mesh
          filename="package://jaka_humanoid/meshes/LINK_R3.STL" />
      </geometry>
      <material
        name="">
        <color
          rgba="0.698039215686274 0.698039215686274 0.698039215686274 1" />
      </material>
    </visual>
    <collision>
      <origin
        xyz="0 0 0"
        rpy="0 0 0" />
      <geometry>
        <mesh
          filename="package://jaka_humanoid/meshes/LINK_R3.STL" />
      </geometry>
    </collision>
  </link>
  <joint
    name="right_hip_yaw_joint"
    type="revolute">
    <origin
      xyz="0 0.183 0"
      rpy="-1.5708 0 0" />
    <parent
      link="right_hip_roll_link" />
    <child
      link="right_hip_yaw_link" />
    <axis
      xyz="0 0 -1" />
    <limit
      lower="-2"
      upper="2"
      effort="500"
      velocity="30" />
  </joint>
  <link
    name="right_knee_link">
    <inertial>
      <origin
        xyz="-0.111706915749733 0.00355722916941977 0.0512342020264392"
        rpy="0 0 0" />
      <mass
        value="8.60704942954802" />
      <inertia
        ixx="0.0274095605302757"
        ixy="-0.00545320862710574"
        ixz="-0.000200202399919482"
        iyy="0.168527364558603"
        iyz="-4.61122421921428E-07"
        izz="0.165684270845229" />
    </inertial>
    <visual>
      <origin
        xyz="0 0 0"
        rpy="0 0 0" />
      <geometry>
        <mesh
          filename="package://jaka_humanoid/meshes/LINK_R4.STL" />
      </geometry>
      <material
        name="">
        <color
          rgba="0.698039215686274 0.698039215686274 0.698039215686274 1" />
      </material>
    </visual>
    <!-- <collision>
      <origin
        xyz="0 0 0"
        rpy="0 0 0" />
      <geometry>
        <mesh
          filename="package://jaka_humanoid/meshes/LINK_R4.STL" />
      </geometry>
    </collision> -->
  </link>
  <joint
    name="right_knee_joint"
    type="revolute">
    <origin
      xyz="-0.0516 -0.005 0.237"
      rpy="0 1.5708 0" />
    <parent
      link="right_hip_yaw_link" />
    <child
      link="right_knee_link" />
    <axis
      xyz="0 0 1" />
    <limit
      lower="-2"
      upper="2"
      effort="500"
      velocity="30" />
  </joint>
  <link
    name="right_ankle_pitch_link">
    <inertial>
      <origin
        xyz="6.626555804079E-08 0.00426165224182175 0.0516144830002066"
        rpy="0 0 0" />
      <mass
        value="4.14002049181103" />
      <inertia
        ixx="0.00859902728227488"
        ixy="2.24153874992742E-09"
        ixz="-8.53395935267242E-07"
        iyy="0.00802808945618975"
        iyz="2.25086689585563E-06"
        izz="0.00870709893603947" />
    </inertial>
    <visual>
      <origin
        xyz="0 0 0"
        rpy="0 0 0" />
      <geometry>
        <mesh
          filename="package://jaka_humanoid/meshes/LINK_R5.STL" />
      </geometry>
      <material
        name="">
        <color
          rgba="0.698039215686274 0.698039215686274 0.698039215686274 1" />
      </material>
    </visual>
    <!-- <collision>
      <origin
        xyz="0 0 0"
        rpy="0 0 0" />
      <geometry>
        <mesh
          filename="package://jaka_humanoid/meshes/LINK_R5.STL" />
      </geometry>
    </collision> -->
  </link>
  <joint
    name="right_ankle_pitch_joint"
    type="revolute">
    <origin
      xyz="-0.37 -0.005 0"
      rpy="0 0 0" />
    <parent
      link="right_knee_link" />
    <child
      link="right_ankle_pitch_link" />
    <axis
      xyz="0 0 1" />
    <limit
      lower="-2"
      upper="2"
      effort="500"
      velocity="30" />
  </joint>
  <link
    name="right_ankle_roll_link">
    <inertial>
      <origin
        xyz="5.58138622626381E-06 0.0507733541183104 -0.0331828582582943"
        rpy="0 0 0" />
      <mass
        value="4.46370359699783" />
      <inertia
        ixx="0.0280531352513672"
        ixy="-5.78596856192022E-07"
        ixz="7.74224976384728E-07"
        iyy="0.0225586719627204"
        iyz="-0.00350808781584849"
        izz="0.0150950458468419" />
    </inertial>
    <visual>
      <origin
        xyz="0 0 0"
        rpy="0 0 0" />
      <geometry>
        <mesh
          filename="package://jaka_humanoid/meshes/LINK_R6.STL" />
      </geometry>
      <material
        name="">
        <color
          rgba="0.698039215686274 0.698039215686274 0.698039215686274 1" />
      </material>
    </visual>
    <collision>
      <origin
        xyz="0 0 0"
        rpy="0 0 0" />
      <geometry>
        <mesh
          filename="package://jaka_humanoid/meshes/LINK_R6.STL" />
      </geometry>
    </collision>
  </link>
  <joint
    name="right_ankle_roll_joint"
    type="revolute">
    <origin
      xyz="0 0.0725 0.0516"
      rpy="1.5708 -1.5708 0" />
    <parent
      link="right_ankle_pitch_link" />
    <child
      link="right_ankle_roll_link" />
    <axis
      xyz="0 0 -1" />
    <limit
      lower="-2"
      upper="2"
      effort="500"
      velocity="30" />
  </joint>
  <link
    name="BODY_LINK">
    <inertial>
      <origin
        xyz="0.00013734007639013 -0.0111829713535279 0.265745363752393"
        rpy="0 0 0" />
      <mass
        value="33.7486973436404" />
      <inertia
        ixx="0.722787001654969"
        ixy="-4.25713904554049E-05"
        ixz="-0.00139461702876621"
        iyy="0.892302471227267"
        iyz="-0.0285817730855974"
        izz="0.348911176678323" />
    </inertial>
    <visual>
      <origin
        xyz="0 0 0"
        rpy="0 0 0" />
      <geometry>
        <mesh
          filename="package://jaka_humanoid/meshes/BODY_LINK.STL" />
      </geometry>
      <material
        name="">
        <color
          rgba="0.898039215686275 0.917647058823529 0.929411764705882 1" />
      </material>
    </visual>
    <collision>
      <origin
        xyz="0 0 0"
        rpy="0 0 0" />
      <geometry>
        <mesh
          filename="package://jaka_humanoid/meshes/BODY_LINK.STL" />
      </geometry>
    </collision>
  </link>
  <joint
    name="BODY_JOINT"
    type="fixed">
    <origin
      xyz="0 0 0.104"
      rpy="0 0 0" />
    <parent
      link="base_link" />
    <child
      link="BODY_LINK" />
    <axis
      xyz="0 0 1" />
    <limit
      lower="-2"
      upper="2"
      effort="500"
      velocity="30" />
  </joint>
  <link
    name="arm-l1">
    <inertial>
      <origin
        xyz="-2.46089330410704E-06 -2.84970787856054E-07 0.164287024146874"
        rpy="0 0 0" />
      <mass
        value="1.49079078470917" />
      <inertia
        ixx="0.00305951889689234"
        ixy="1.23224145484232E-07"
        ixz="4.7234806846658E-08"
        iyy="0.00378376232211114"
        iyz="-3.76862388057772E-08"
        izz="0.00212531859055584" />
    </inertial>
    <visual>
      <origin
        xyz="0 0 0"
        rpy="0 0 0" />
      <geometry>
        <mesh
          filename="package://jaka_humanoid/meshes/arm-l1.STL" />
      </geometry>
      <material
        name="">
        <color
          rgba="0.898039215686275 0.917647058823529 0.929411764705882 1" />
      </material>
    </visual>
    <collision>
      <origin
        xyz="0 0 0"
        rpy="0 0 0" />
      <geometry>
        <mesh
          filename="package://jaka_humanoid/meshes/arm-l1.STL" />
      </geometry>
    </collision>
  </link>
  <joint
    name="arm-lj1"
    type="fixed">
    <origin
      xyz="-0.06 0 0.4302"
      rpy="1.5708 0 -1.5708" />
    <parent
      link="BODY_LINK" />
    <child
      link="arm-l1" />
    <axis
      xyz="0 0 1" />
    <limit
      lower="-2"
      upper="2"
      effort="500"
      velocity="30" />
  </joint>
  <link
    name="arm-l2">
    <inertial>
      <origin
        xyz="1.7109844037938E-05 -0.0452985718637721 -0.000762954989173337"
        rpy="0 0 0" />
      <mass
        value="2.70256303290924" />
      <inertia
        ixx="0.00984922869542074"
        ixy="3.34426654213901E-06"
        ixz="1.15726850653024E-09"
        iyy="0.00588632041233297"
        iyz="9.35439353884173E-05"
        izz="0.00747853188064791" />
    </inertial>
    <visual>
      <origin
        xyz="0 0 0"
        rpy="0 0 0" />
      <geometry>
        <mesh
          filename="package://jaka_humanoid/meshes/arm-l2.STL" />
      </geometry>
      <material
        name="">
        <color
          rgba="0.898039215686275 0.917647058823529 0.929411764705882 1" />
      </material>
    </visual>
    <collision>
      <origin
        xyz="0 0 0"
        rpy="0 0 0" />
      <geometry>
        <mesh
          filename="package://jaka_humanoid/meshes/arm-l2.STL" />
      </geometry>
    </collision>
  </link>
  <joint
    name="arm-lj2"
    type="fixed">
    <origin
      xyz="0 0 0.2075"
      rpy="-1.5708 0 0" />
    <parent
      link="arm-l1" />
    <child
      link="arm-l2" />
    <axis
      xyz="0 0 1" />
    <limit
      lower="-2"
      upper="2"
      effort="500"
      velocity="30" />
  </joint>
  <link
    name="arm-l3">
    <inertial>
      <origin
        xyz="-0.00699744559038216 -0.000446274066820407 0.236701003976312"
        rpy="0 0 0" />
      <mass
        value="3.54789151265847" />
      <inertia
        ixx="0.0185299009076935"
        ixy="1.22432465180445E-06"
        ixz="0.000124494468855343"
        iyy="0.0186988857026103"
        iyz="-1.68802472982149E-05"
        izz="0.00375500734997881" />
    </inertial>
    <visual>
      <origin
        xyz="0 0 0"
        rpy="0 0 0" />
      <geometry>
        <mesh
          filename="package://jaka_humanoid/meshes/arm-l3.STL" />
      </geometry>
      <material
        name="">
        <color
          rgba="0.898039215686275 0.917647058823529 0.929411764705882 1" />
      </material>
    </visual>
    <collision>
      <origin
        xyz="0 0 0"
        rpy="0 0 0" />
      <geometry>
        <mesh
          filename="package://jaka_humanoid/meshes/arm-l3.STL" />
      </geometry>
    </collision>
  </link>
  <joint
    name="arm-lj3"
    type="fixed">
    <origin
      xyz="0 0 0"
      rpy="-1.5708 0 -3.1416" />
    <parent
      link="arm-l2" />
    <child
      link="arm-l3" />
    <axis
      xyz="0 0 1" />
    <limit
      lower="-2"
      upper="2"
      effort="500"
      velocity="30" />
  </joint>
  <link
    name="arm-l4">
    <inertial>
      <origin
        xyz="0.00464516953010592 -0.0316039283529114 0.000428142213802829"
        rpy="0 0 0" />
      <mass
        value="1.47374287378551" />
      <inertia
        ixx="0.00379329555273283"
        ixy="0.000160245369673316"
        ixz="2.06610249481922E-07"
        iyy="0.00225584846210298"
        iyz="8.03453868461583E-06"
        izz="0.00281134624088121" />
    </inertial>
    <visual>
      <origin
        xyz="0 0 0"
        rpy="0 0 0" />
      <geometry>
        <mesh
          filename="package://jaka_humanoid/meshes/arm-l4.STL" />
      </geometry>
      <material
        name="">
        <color
          rgba="0.898039215686275 0.917647058823529 0.929411764705882 1" />
      </material>
    </visual>
    <collision>
      <origin
        xyz="0 0 0"
        rpy="0 0 0" />
      <geometry>
        <mesh
          filename="package://jaka_humanoid/meshes/arm-l4.STL" />
      </geometry>
    </collision>
  </link>
  <joint
    name="arm-lj4"
    type="fixed">
    <origin
      xyz="0.00040027 0 0.33028"
      rpy="-1.5708 0 3.1416" />
    <parent
      link="arm-l3" />
    <child
      link="arm-l4" />
    <axis
      xyz="0 0 1" />
    <limit
      lower="-2"
      upper="2"
      effort="500"
      velocity="30" />
  </joint>
  <link
    name="arm-l5">
    <inertial>
      <origin
        xyz="-2.28024774949487E-06 0.00408004171070475 0.183530036849259"
        rpy="0 0 0" />
      <mass
        value="2.28087734206239" />
      <inertia
        ixx="0.00549251858394413"
        ixy="1.60017198738006E-07"
        ixz="1.71172962810271E-07"
        iyy="0.00557865414731656"
        iyz="-0.00038426086153489"
        izz="0.00195901367824945" />
    </inertial>
    <visual>
      <origin
        xyz="0 0 0"
        rpy="0 0 0" />
      <geometry>
        <mesh
          filename="package://jaka_humanoid/meshes/arm-l5.STL" />
      </geometry>
      <material
        name="">
        <color
          rgba="0.898039215686275 0.917647058823529 0.929411764705882 1" />
      </material>
    </visual>
    <collision>
      <origin
        xyz="0 0 0"
        rpy="0 0 0" />
      <geometry>
        <mesh
          filename="package://jaka_humanoid/meshes/arm-l5.STL" />
      </geometry>
    </collision>
  </link>
  <joint
    name="arm-lj5"
    type="fixed">
    <origin
      xyz="0 0 0"
      rpy="-1.5708 0 3.1416" />
    <parent
      link="arm-l4" />
    <child
      link="arm-l5" />
    <axis
      xyz="0 0 1" />
    <limit
      lower="-2"
      upper="2"
      effort="500"
      velocity="30" />
  </joint>
  <link
    name="arm-l6">
    <inertial>
      <origin
        xyz="-2.14081846389158E-07 -0.0803636128317545 0.00616002744150357"
        rpy="0 0 0" />
      <mass
        value="1.58792603771551" />
      <inertia
        ixx="0.00366000115507612"
        ixy="2.25894931082097E-08"
        ixz="7.18926190526462E-09"
        iyy="0.00142870340307534"
        iyz="-0.000705165358365624"
        izz="0.00347714999503412" />
    </inertial>
    <visual>
      <origin
        xyz="0 0 0"
        rpy="0 0 0" />
      <geometry>
        <mesh
          filename="package://jaka_humanoid/meshes/arm-l6.STL" />
      </geometry>
      <material
        name="">
        <color
          rgba="0.898039215686275 0.917647058823529 0.929411764705882 1" />
      </material>
    </visual>
    <collision>
      <origin
        xyz="0 0 0"
        rpy="0 0 0" />
      <geometry>
        <mesh
          filename="package://jaka_humanoid/meshes/arm-l6.STL" />
      </geometry>
    </collision>
  </link>
  <joint
    name="arm-lj6"
    type="fixed">
    <origin
      xyz="0 0 0.23494"
      rpy="-1.5708 0 -3.1416" />
    <parent
      link="arm-l5" />
    <child
      link="arm-l6" />
    <axis
      xyz="0 0 1" />
    <limit
      lower="-2"
      upper="2"
      effort="500"
      velocity="30" />
  </joint>
  <link
    name="arm-l7">
    <inertial>
      <origin
        xyz="2.69436503518017E-07 -2.95979202020735E-05 0.164217274875879"
        rpy="0 0 0" />
      <mass
        value="0.634983447813082" />
      <inertia
        ixx="0.000369700889597726"
        ixy="-7.65481275286183E-20"
        ixz="-1.05007339976448E-17"
        iyy="0.000370207331921778"
        iyz="4.29757109352668E-07"
        izz="0.000512144748392785" />
    </inertial>
    <visual>
      <origin
        xyz="0 0 0"
        rpy="0 0 0" />
      <geometry>
        <mesh
          filename="package://jaka_humanoid/meshes/arm-l7.STL" />
      </geometry>
      <material
        name="">
        <color
          rgba="1 1 1 1" />
      </material>
    </visual>
    <collision>
      <origin
        xyz="0 0 0"
        rpy="0 0 0" />
      <geometry>
        <mesh
          filename="package://jaka_humanoid/meshes/arm-l7.STL" />
      </geometry>
    </collision>
  </link>
  <joint
    name="arm-lj7"
    type="fixed">
    <origin
      xyz="0 0 0"
      rpy="1.5708 0 0" />
    <parent
      link="arm-l6" />
    <child
      link="arm-l7" />
    <axis
      xyz="0 0 1" />
    <limit
      lower="-2"
      upper="2"
      effort="500"
      velocity="30" />
  </joint>
  <link
    name="arm-lt">
    <inertial>
      <origin
        xyz="5.55111512312578E-17 6.03031846679869E-10 -0.00099999999999989"
        rpy="0 0 0" />
      <mass
        value="0.00155862265526229" />
      <inertia
        ixx="9.7178498990338E-08"
        ixy="4.26142661000391E-27"
        ixz="-7.09361850234105E-21"
        iyy="9.71784989903729E-08"
        iyz="-5.79751342725907E-14"
        izz="1.93317916210466E-07" />
    </inertial>
    <visual>
      <origin
        xyz="0 0 0"
        rpy="0 0 0" />
      <geometry>
        <mesh
          filename="package://jaka_humanoid/meshes/arm-lt.STL" />
      </geometry>
      <material
        name="">
        <color
          rgba="0.792156862745098 0.819607843137255 0.933333333333333 1" />
      </material>
    </visual>
    <collision>
      <origin
        xyz="0 0 0"
        rpy="0 0 0" />
      <geometry>
        <mesh
          filename="package://jaka_humanoid/meshes/arm-lt.STL" />
      </geometry>
    </collision>
  </link>
  <joint
    name="arm-ljt"
    type="fixed">
    <origin
      xyz="0 0 0.19077"
      rpy="0 0 0" />
    <parent
      link="arm-l7" />
    <child
      link="arm-lt" />
    <axis
      xyz="0 0 0" />
  </joint>
  <link
    name="arm-r1">
    <inertial>
      <origin
        xyz="2.46089331307903E-06 2.84970779862448E-07 0.16428702414733"
        rpy="0 0 0" />
      <mass
        value="1.4907907847092" />
      <inertia
        ixx="0.00305951889689245"
        ixy="1.23224145462198E-07"
        ixz="-4.72348068440876E-08"
        iyy="0.00378376232211126"
        iyz="3.76862386712988E-08"
        izz="0.00212531859055588" />
    </inertial>
    <visual>
      <origin
        xyz="0 0 0"
        rpy="0 0 0" />
      <geometry>
        <mesh
          filename="package://jaka_humanoid/meshes/arm-r1.STL" />
      </geometry>
      <material
        name="">
        <color
          rgba="0.898039215686275 0.917647058823529 0.929411764705882 1" />
      </material>
    </visual>
    <collision>
      <origin
        xyz="0 0 0"
        rpy="0 0 0" />
      <geometry>
        <mesh
          filename="package://jaka_humanoid/meshes/arm-r1.STL" />
      </geometry>
    </collision>
  </link>
  <joint
    name="arm-rj1"
    type="fixed">
    <origin
      xyz="0.06 0 0.4302"
      rpy="1.5708 0 1.5708" />
    <parent
      link="BODY_LINK" />
    <child
      link="arm-r1" />
    <axis
      xyz="0 0 1" />
    <limit
      lower="-2"
      upper="2"
      effort="500"
      velocity="30" />
  </joint>
  <link
    name="arm-r2">
    <inertial>
      <origin
        xyz="1.7109844001835E-05 -0.0452985718642643 -0.000762954989178555"
        rpy="0 0 0" />
      <mass
        value="2.70256303290934" />
      <inertia
        ixx="0.0098492286954209"
        ixy="3.34426654176547E-06"
        ixz="1.15726845506335E-09"
        iyy="0.0058863204123332"
        iyz="9.35439353883321E-05"
        izz="0.00747853188064819" />
    </inertial>
    <visual>
      <origin
        xyz="0 0 0"
        rpy="0 0 0" />
      <geometry>
        <mesh
          filename="package://jaka_humanoid/meshes/arm-r2.STL" />
      </geometry>
      <material
        name="">
        <color
          rgba="0.898039215686275 0.917647058823529 0.929411764705882 1" />
      </material>
    </visual>
    <collision>
      <origin
        xyz="0 0 0"
        rpy="0 0 0" />
      <geometry>
        <mesh
          filename="package://jaka_humanoid/meshes/arm-r2.STL" />
      </geometry>
    </collision>
  </link>
  <joint
    name="arm-rj2"
    type="fixed">
    <origin
      xyz="0 0 0.2075"
      rpy="-1.5708 0 3.1416" />
    <parent
      link="arm-r1" />
    <child
      link="arm-r2" />
    <axis
      xyz="0 0 1" />
    <limit
      lower="-2"
      upper="2"
      effort="500"
      velocity="30" />
  </joint>
  <link
    name="arm-r3">
    <inertial>
      <origin
        xyz="0.00699744558994671 0.000445736586063172 0.236701004986568"
        rpy="0 0 0" />
      <mass
        value="3.54789151268406" />
      <inertia
        ixx="0.0185299009074185"
        ixy="1.22460738296824E-06"
        ixz="-0.000124494466263207"
        iyy="0.0186988856256308"
        iyz="1.69141808217164E-05"
        izz="0.00375500742679508" />
    </inertial>
    <visual>
      <origin
        xyz="0 0 0"
        rpy="0 0 0" />
      <geometry>
        <mesh
          filename="package://jaka_humanoid/meshes/arm-r3.STL" />
      </geometry>
      <material
        name="">
        <color
          rgba="0.898039215686275 0.917647058823529 0.929411764705882 1" />
      </material>
    </visual>
    <collision>
      <origin
        xyz="0 0 0"
        rpy="0 0 0" />
      <geometry>
        <mesh
          filename="package://jaka_humanoid/meshes/arm-r3.STL" />
      </geometry>
    </collision>
  </link>
  <joint
    name="arm-rj3"
    type="fixed">
    <origin
      xyz="0 0 0"
      rpy="1.5708 0 0" />
    <parent
      link="arm-r2" />
    <child
      link="arm-r3" />
    <axis
      xyz="0 0 1" />
    <limit
      lower="-2"
      upper="2"
      effort="500"
      velocity="30" />
  </joint>
  <link
    name="arm-r4">
    <inertial>
      <origin
        xyz="0.00464517591591148 -0.0316040840757925 0.000428238492313104"
        rpy="0 0 0" />
      <mass
        value="1.47374201793622" />
      <inertia
        ixx="0.00379329094146422"
        ixy="0.000160244415781904"
        ixz="2.07234499079314E-07"
        iyy="0.00225584681208052"
        iyz="8.03201567915385E-06"
        izz="0.00281134306624416" />
    </inertial>
    <visual>
      <origin
        xyz="0 0 0"
        rpy="0 0 0" />
      <geometry>
        <mesh
          filename="package://jaka_humanoid/meshes/arm-r4.STL" />
      </geometry>
      <material
        name="">
        <color
          rgba="0.898039215686275 0.917647058823529 0.929411764705882 1" />
      </material>
    </visual>
    <collision>
      <origin
        xyz="0 0 0"
        rpy="0 0 0" />
      <geometry>
        <mesh
          filename="package://jaka_humanoid/meshes/arm-r4.STL" />
      </geometry>
    </collision>
  </link>
  <joint
    name="arm-rj4"
    type="fixed">
    <origin
      xyz="-0.00040027 0 0.33028"
      rpy="-1.5708 0 0" />
    <parent
      link="arm-r3" />
    <child
      link="arm-r4" />
    <axis
      xyz="0 0 1" />
    <limit
      lower="-2"
      upper="2"
      effort="500"
      velocity="30" />
  </joint>
  <link
    name="arm-r5">
    <inertial>
      <origin
        xyz="-2.73577081470744E-06 0.00407883931490616 0.183529506912868"
        rpy="0 0 0" />
      <mass
        value="2.28081200666416" />
      <inertia
        ixx="0.00549240002759694"
        ixy="2.02933287543883E-07"
        ixz="1.92989658554136E-07"
        iyy="0.00557858764336004"
        iyz="-0.0003841922444168"
        izz="0.00195892105469368" />
    </inertial>
    <visual>
      <origin
        xyz="0 0 0"
        rpy="0 0 0" />
      <geometry>
        <mesh
          filename="package://jaka_humanoid/meshes/arm-r5.STL" />
      </geometry>
      <material
        name="">
        <color
          rgba="0.898039215686275 0.917647058823529 0.929411764705882 1" />
      </material>
    </visual>
    <collision>
      <origin
        xyz="0 0 0"
        rpy="0 0 0" />
      <geometry>
        <mesh
          filename="package://jaka_humanoid/meshes/arm-r5.STL" />
      </geometry>
    </collision>
  </link>
  <joint
    name="arm-rj5"
    type="fixed">
    <origin
      xyz="0 0 0"
      rpy="1.5708 0 0" />
    <parent
      link="arm-r4" />
    <child
      link="arm-r5" />
    <axis
      xyz="0 0 1" />
    <limit
      lower="-2"
      upper="2"
      effort="500"
      velocity="30" />
  </joint>
  <link
    name="arm-r6">
    <inertial>
      <origin
        xyz="-2.14082035737695E-07 -0.080363595139343 0.00615553189983786"
        rpy="0 0 0" />
      <mass
        value="1.5879260377349" />
      <inertia
        ixx="0.00366000115518685"
        ixy="2.25895321396928E-08"
        ixz="7.18919548911259E-09"
        iyy="0.0014286993501888"
        iyz="-0.000705159471653687"
        izz="0.00347715404809764" />
    </inertial>
    <visual>
      <origin
        xyz="0 0 0"
        rpy="0 0 0" />
      <geometry>
        <mesh
          filename="package://jaka_humanoid/meshes/arm-r6.STL" />
      </geometry>
      <material
        name="">
        <color
          rgba="0.898039215686275 0.917647058823529 0.929411764705882 1" />
      </material>
    </visual>
    <collision>
      <origin
        xyz="0 0 0"
        rpy="0 0 0" />
      <geometry>
        <mesh
          filename="package://jaka_humanoid/meshes/arm-r6.STL" />
      </geometry>
    </collision>
  </link>
  <joint
    name="arm-rj6"
    type="fixed">
    <origin
      xyz="0 0 0.23494"
      rpy="-1.5708 0 -3.1416" />
    <parent
      link="arm-r5" />
    <child
      link="arm-r6" />
    <axis
      xyz="0 0 1" />
    <limit
      lower="-2"
      upper="2"
      effort="500"
      velocity="30" />
  </joint>
  <link
    name="arm-r7">
    <inertial>
      <origin
        xyz="2.69436562498615E-07 -3.38524873837454E-05 0.164217274971439"
        rpy="0 0 0" />
      <mass
        value="0.63498344781308" />
      <inertia
        ixx="0.000369700889597724"
        ixy="1.28085815926539E-19"
        ixz="4.05201352102206E-17"
        iyy="0.000370207334392976"
        iyz="4.30165001831703E-07"
        izz="0.000512144745921583" />
    </inertial>
    <visual>
      <origin
        xyz="0 0 0"
        rpy="0 0 0" />
      <geometry>
        <mesh
          filename="package://jaka_humanoid/meshes/arm-r7.STL" />
      </geometry>
      <material
        name="">
        <color
          rgba="1 1 1 1" />
      </material>
    </visual>
    <collision>
      <origin
        xyz="0 0 0"
        rpy="0 0 0" />
      <geometry>
        <mesh
          filename="package://jaka_humanoid/meshes/arm-r7.STL" />
      </geometry>
    </collision>
  </link>
  <joint
    name="arm-rj7"
    type="fixed">
    <origin
      xyz="0 0 0"
      rpy="1.5708 0 0" />
    <parent
      link="arm-r6" />
    <child
      link="arm-r7" />
    <axis
      xyz="0 0 1" />
    <limit
      lower="-2"
      upper="2"
      effort="500"
      velocity="30" />
  </joint>
  <link
    name="arm-rt">
    <inertial>
      <origin
        xyz="-2.0122792321331E-16 -2.27071683678304E-09 -0.000999999999998558"
        rpy="0 0 0" />
      <mass
        value="0.0015586226552622" />
      <inertia
        ixx="9.71784989903325E-08"
        ixy="6.21085967898607E-26"
        ixz="2.73548136781045E-20"
        iyy="9.71784989908281E-08"
        iyz="2.18305404600831E-13"
        izz="1.93317916209994E-07" />
    </inertial>
    <visual>
      <origin
        xyz="0 0 0"
        rpy="0 0 0" />
      <geometry>
        <mesh
          filename="package://jaka_humanoid/meshes/arm-rt.STL" />
      </geometry>
      <material
        name="">
        <color
          rgba="0.792156862745098 0.819607843137255 0.933333333333333 1" />
      </material>
    </visual>
    <collision>
      <origin
        xyz="0 0 0"
        rpy="0 0 0" />
      <geometry>
        <mesh
          filename="package://jaka_humanoid/meshes/arm-rt.STL" />
      </geometry>
    </collision>
  </link>
  <joint
    name="ram-rjt"
    type="fixed">
    <origin
      xyz="0 0 0.19077"
      rpy="0 0 0" />
    <parent
      link="arm-r7" />
    <child
      link="arm-rt" />
    <axis
      xyz="0 0 0" />
  </joint>
</robot>